<?xml version="1.0" ?>
<!-- =================================================================================== -->
<!-- |    This document was autogenerated by xacro from seven_link.urdf.xacro          | -->
<!-- |    EDITING THIS FILE BY HAND IS NOT RECOMMENDED                                 | -->
<!-- =================================================================================== -->
<robot name="reacher_seven_links">
  <link name="base">
    <inertial>
      <origin rpy="0.00000 -0.00000 0.00000" xyz="0.00000 0.00000 0.00000"/>
      <mass value="0.00000"/>
      <inertia ixx="0.00000" ixy="0" ixz="0" iyy="0.00000" iyz="0" izz="0.00000"/>
    </inertial>
    <collision>
      <origin rpy="0.00000 -0.00000 0.00000" xyz="0.00000 0.00000 0.00000"/>
      <geometry>
        <sphere radius="0.01000"/>
      </geometry>
    </collision>
  </link>
  <link name="cylinder_0">
    <inertial>
      <origin rpy="0.00000 -0.00000 0.00000" xyz="0.02500 0.00000 0.00000"/>
      <mass value="0.001"/>
      <inertia ixx="0.00000" ixy="0" ixz="0" iyy="0.00004" iyz="0" izz="0.00004"/>
    </inertial>
    <collision>
      <origin rpy="0.00000 1.57080 -0.00000" xyz="0.02500 0.00000 0.00000"/>
      <geometry>
        <capsule length="0.05000" radius="0.01000"/>
      </geometry>
    </collision>
  </link>
  <joint name="joint_revolute_0" type="continuous">
    <parent link="base"/>
    <child link="cylinder_0"/>
    <limit effort="80.0" velocity="5.0"/>
    <dynamics damping="0" friction="0.0001"/>
    <origin rpy="0.00000 -0.00000 0.00000" xyz="0.00000 0.00000 0.00000"/>
    <axis xyz="0.00000 0.00000 1.00000"/>
  </joint>
  <link name="invisible_1">
    <inertial>
      <origin rpy="0.00000 -0.00000 0.00000" xyz="0.00000 0.00000 0.00000"/>
      <mass value="0.00000"/>
      <inertia ixx="0.00000" ixy="0" ixz="0" iyy="0.00000" iyz="0" izz="0.00000"/>
    </inertial>
  </link>
  <link name="cylinder_1">
    <inertial>
      <origin rpy="0.00000 -0.00000 0.00000" xyz="0.02500 0.00000 0.00000"/>
      <mass value="0.001"/>
      <inertia ixx="0.00000" ixy="0" ixz="0" iyy="0.00004" iyz="0" izz="0.00004"/>
    </inertial>
    <collision>
      <origin rpy="0.00000 1.57080 -0.00000" xyz="0.02500 0.00000 0.00000"/>
      <geometry>
        <capsule length="0.05000" radius="0.01000"/>
      </geometry>
    </collision>
  </link>
  <link name="invisible_2">
    <inertial>
      <origin rpy="0.00000 -0.00000 0.00000" xyz="0.00000 0.00000 0.00000"/>
      <mass value="0.00000"/>
      <inertia ixx="0.00000" ixy="0" ixz="0" iyy="0.00000" iyz="0" izz="0.00000"/>
    </inertial>
  </link>
  <link name="cylinder_2">
    <inertial>
      <origin rpy="0.00000 -0.00000 0.00000" xyz="0.02500 0.00000 0.00000"/>
      <mass value="0.001"/>
      <inertia ixx="0.00000" ixy="0" ixz="0" iyy="0.00004" iyz="0" izz="0.00004"/>
    </inertial>
    <collision>
      <origin rpy="0.00000 1.57080 -0.00000" xyz="0.02500 0.00000 0.00000"/>
      <geometry>
        <capsule length="0.05000" radius="0.01000"/>
      </geometry>
    </collision>
  </link>
  <link name="invisible_3">
    <inertial>
      <origin rpy="0.00000 -0.00000 0.00000" xyz="0.00000 0.00000 0.00000"/>
      <mass value="0.00000"/>
      <inertia ixx="0.00000" ixy="0" ixz="0" iyy="0.00000" iyz="0" izz="0.00000"/>
    </inertial>
  </link>
  <link name="cylinder_3">
    <inertial>
      <origin rpy="0.00000 -0.00000 0.00000" xyz="0.02500 0.00000 0.00000"/>
      <mass value="0.001"/>
      <inertia ixx="0.00000" ixy="0" ixz="0" iyy="0.00004" iyz="0" izz="0.00004"/>
    </inertial>
    <collision>
      <origin rpy="0.00000 1.57080 -0.00000" xyz="0.02500 0.00000 0.00000"/>
      <geometry>
        <capsule length="0.05000" radius="0.01000"/>
      </geometry>
    </collision>
  </link>
  <link name="invisible_4">
    <inertial>
      <origin rpy="0.00000 -0.00000 0.00000" xyz="0.00000 0.00000 0.00000"/>
      <mass value="0.00000"/>
      <inertia ixx="0.00000" ixy="0" ixz="0" iyy="0.00000" iyz="0" izz="0.00000"/>
    </inertial>
  </link>
  <link name="cylinder_4">
    <inertial>
      <origin rpy="0.00000 -0.00000 0.00000" xyz="0.02500 0.00000 0.00000"/>
      <mass value="0.001"/>
      <inertia ixx="0.00000" ixy="0" ixz="0" iyy="0.00004" iyz="0" izz="0.00004"/>
    </inertial>
    <collision>
      <origin rpy="0.00000 1.57080 -0.00000" xyz="0.02500 0.00000 0.00000"/>
      <geometry>
        <capsule length="0.05000" radius="0.01000"/>
      </geometry>
    </collision>
  </link>
  <link name="invisible_5">
    <inertial>
      <origin rpy="0.00000 -0.00000 0.00000" xyz="0.00000 0.00000 0.00000"/>
      <mass value="0.00000"/>
      <inertia ixx="0.00000" ixy="0" ixz="0" iyy="0.00000" iyz="0" izz="0.00000"/>
    </inertial>
  </link>
  <link name="cylinder_5">
    <inertial>
      <origin rpy="0.00000 -0.00000 0.00000" xyz="0.02500 0.00000 0.00000"/>
      <mass value="0.001"/>
      <inertia ixx="0.00000" ixy="0" ixz="0" iyy="0.00004" iyz="0" izz="0.00004"/>
    </inertial>
    <collision>
      <origin rpy="0.00000 1.57080 -0.00000" xyz="0.02500 0.00000 0.00000"/>
      <geometry>
        <capsule length="0.05000" radius="0.01000"/>
      </geometry>
    </collision>
  </link>
  <link name="invisible_6">
    <inertial>
      <origin rpy="0.00000 -0.00000 0.00000" xyz="0.00000 0.00000 0.00000"/>
      <mass value="0.00000"/>
      <inertia ixx="0.00000" ixy="0" ixz="0" iyy="0.00000" iyz="0" izz="0.00000"/>
    </inertial>
  </link>
  <link name="cylinder_6">
    <inertial>
      <origin rpy="0.00000 -0.00000 0.00000" xyz="0.02500 0.00000 0.00000"/>
      <mass value="0.001"/>
      <inertia ixx="0.00000" ixy="0" ixz="0" iyy="0.00004" iyz="0" izz="0.00004"/>
    </inertial>
    <collision>
      <origin rpy="0.00000 1.57080 -0.00000" xyz="0.02500 0.00000 0.00000"/>
      <geometry>
        <capsule length="0.05000" radius="0.01000"/>
      </geometry>
    </collision>
  </link>
  <joint name="joint_revolute_1" type="revolute">
    <parent link="cylinder_0"/>
    <child link="invisible_1"/>
    <limit effort="80" lower="-3.05" upper="3.05" velocity="5.0"/>
    <dynamics damping="0.0001" friction="0.0001"/>
    <origin rpy="0.00000 -0.00000 0.00000" xyz="0.05000 0.00000 0.00000"/>
    <axis xyz="0.00000 0.00000 1.00000"/>
  </joint>
  <joint name="joint_fix_1" type="fixed">
    <parent link="invisible_1"/>
    <child link="cylinder_1"/>
    <origin rpy="0.00000 -0.00000 0.00000" xyz="0.00000 0.00000 0.00000"/>
  </joint>
  <joint name="joint_revolute_2" type="revolute">
    <parent link="cylinder_1"/>
    <child link="invisible_2"/>
    <limit effort="80" lower="-3.05" upper="3.05" velocity="5.0"/>
    <dynamics damping="0.0001" friction="0.0001"/>
    <origin rpy="0.00000 -0.00000 0.00000" xyz="0.05000 0.00000 0.00000"/>
    <axis xyz="0.00000 0.00000 1.00000"/>
  </joint>
  <joint name="joint_fix_2" type="fixed">
    <parent link="invisible_2"/>
    <child link="cylinder_2"/>
    <origin rpy="0.00000 -0.00000 0.00000" xyz="0.00000 0.00000 0.00000"/>
  </joint>
  <joint name="joint_revolute_3" type="revolute">
    <parent link="cylinder_2"/>
    <child link="invisible_3"/>
    <limit effort="80" lower="-3.05" upper="3.05" velocity="5.0"/>
    <dynamics damping="0.0001" friction="0.0001"/>
    <origin rpy="0.00000 -0.00000 0.00000" xyz="0.05000 0.00000 0.00000"/>
    <axis xyz="0.00000 0.00000 1.00000"/>
  </joint>
  <joint name="joint_fix_3" type="fixed">
    <parent link="invisible_3"/>
    <child link="cylinder_3"/>
    <origin rpy="0.00000 -0.00000 0.00000" xyz="0.00000 0.00000 0.00000"/>
  </joint>
  <joint name="joint_revolute_4" type="revolute">
    <parent link="cylinder_3"/>
    <child link="invisible_4"/>
    <limit effort="80" lower="-3.05" upper="3.05" velocity="5.0"/>
    <dynamics damping="0.0001" friction="0.0001"/>
    <origin rpy="0.00000 -0.00000 0.00000" xyz="0.05000 0.00000 0.00000"/>
    <axis xyz="0.00000 0.00000 1.00000"/>
  </joint>
  <joint name="joint_fix_4" type="fixed">
    <parent link="invisible_4"/>
    <child link="cylinder_4"/>
    <origin rpy="0.00000 -0.00000 0.00000" xyz="0.00000 0.00000 0.00000"/>
  </joint>
  <joint name="joint_revolute_5" type="revolute">
    <parent link="cylinder_4"/>
    <child link="invisible_5"/>
    <limit effort="80" lower="-3.05" upper="3.05" velocity="5.0"/>
    <dynamics damping="0.0001" friction="0.0001"/>
    <origin rpy="0.00000 -0.00000 0.00000" xyz="0.05000 0.00000 0.00000"/>
    <axis xyz="0.00000 0.00000 1.00000"/>
  </joint>
  <joint name="joint_fix_5" type="fixed">
    <parent link="invisible_5"/>
    <child link="cylinder_5"/>
    <origin rpy="0.00000 -0.00000 0.00000" xyz="0.00000 0.00000 0.00000"/>
  </joint>
  <joint name="joint_revolute_6" type="revolute">
    <parent link="cylinder_5"/>
    <child link="invisible_6"/>
    <limit effort="80" lower="-3.05" upper="3.05" velocity="5.0"/>
    <dynamics damping="0.0001" friction="0.0001"/>
    <origin rpy="0.00000 -0.00000 0.00000" xyz="0.05000 0.00000 0.00000"/>
    <axis xyz="0.00000 0.00000 1.00000"/>
  </joint>
  <joint name="joint_fix_6" type="fixed">
    <parent link="invisible_6"/>
    <child link="cylinder_6"/>
    <origin rpy="0.00000 -0.00000 0.00000" xyz="0.00000 0.00000 0.00000"/>
  </joint>
  <link name="fingertip">
    <inertial>
      <origin rpy="0.00000 -0.00000 0.00000" xyz="0.00000 0.00000 0.00000"/>
      <mass value="0.000"/>
      <inertia ixx="0.00000" ixy="0" ixz="0" iyy="0.00000" iyz="0" izz="0.00000"/>
    </inertial>
    <collision>
      <origin rpy="0.00000 -0.00000 0.00000" xyz="0.00000 0.00000 0.00000"/>
      <geometry>
        <sphere radius="0.01000"/>
      </geometry>
    </collision>
  </link>
  <joint name="joint_fingertip" type="fixed">
    <parent link="cylinder_6"/>
    <child link="fingertip"/>
    <origin rpy="0.00000 -0.00000 0.00000" xyz="0.06000 0.00000 0.00000"/>
    <axis xyz="0.00000 0.00000 0.00000"/>
  </joint>
</robot>
